以下の各関数 f3 から f12 までを実行すると何が出力されるか予想し実際に確認しなさい。
またその理由を 2、3 行のテキスト、図のいずれかまたは両方で説明しなさい。テキスト・図は f1 の解答例を参考にしなさい。
出題範囲: 13.2

# 予想

- f3  
  すぐに A が出力され、finally の C が出力される(B は catch できなさそう)

- f4  
  2 秒後に A が出力され、40 が返却される。  
  1000 秒後に B が出力され、100 が返却される。  
  v に何の値が渡されるか？  
  v には 2 つ目に実行された 100 の値が渡されると思うので、最後に 100 が出力される。

- f5
  2 秒後に A が出力され、40 が返却される。：f4 と同じ
  次は Promise が渡されるので、処理は先に進み、v には 40 が渡されると思うので、40 が出力される。  
  その後、B が出力される。

- f6  
  1 秒後に A が出力され、その 1 秒後に B が出力される。  
  そのあと、A が出力されてから、2 秒後に C が出力されるかどうか？  
  2 秒後に出力されそう。

- f7  
  1 行後に A が出力され、その 2 秒後に C が出力される。
  Promise が解決済みなので、B は出力されないと思う。

- f8  
  catch でどのエラーを拾うか？  
  1 秒後に errX を拾い、その後 errY を拾う。
  最後に A が出力される。

- f9  
  最初の then では何をしているか？  
  1 秒後に errY を拾い、最後に A が出力される。

- f10  
  1 秒後に A が出力されて終わりそう。errY は拾われない。理由？

- f11  
  こちらはエラーを catch できそう(なんとなく)

- f12  
  反対にこちらはエラーを catch できなさそう(なんとなく)

# 結果

- f3
  C->A の順で出力され、その後 X の Error が catch された

- f4
  A->B->100 の順で出力された

- f5
  B->A->40 の順で出力された

- f6
  A->B->C の順で出力された

- f7
  A->B->C の順で出力された

- f8
  X->A の順で出力された

- f9
  Y->A の順で出力された

- f10
  A が出力され、その後 Y の Error が catch された

- f11
  X だけ出力された

- f12
  X の Error が catch されただけ

# 理由

- f3
  finally が先に実行される理由？
  0 秒後に try の中が実行されるが、先に finally の方が実行され、C が出力される。
  A が実行され、X が実行される。
  例外は catch できないので、B は出力されない。

- f4
  2 秒後に 1 つ目の then が実行されるので、A が出力。
  その際に 40 が return される。
  その後、2 つ目の then が実行され、1 秒後に B が出力され、100 が return され、最後に 100 が出力される。
  40 は 100 で上書きされる。

- f5
  2 つ目の then 内の Promise が解消されるまで、1 つ目の then が実行されないので、まず B が出力され、100 が return される。
  その後、1 つ目の then が実行され、A が出力され、40 が return されるので、最後の then で 40 が出力される。

- f6
  1 つ目の Promise でも複数 then が呼び出しできるので(?)
  1 秒後に A が出力、1 秒後に B が出力、2 秒後に C が出力される。

- f7
  まずは 1 つ目の then が実行されるので、A が出力される。
  2 秒後に p は解決しているが、呼び出し可能(？)なので、そのまま B と C が出力される。

- f8
  1 つ目の then で X の Error が出力される。
  そこで、処理が終了するので、2 つ目の then は実行されない。
  finally は必ず実行されるので A が出力される。

- f9
  1 つ目の then は実行されるが、特に出力がないので、そのまま次の then が実行され、Y の Error が出力される。
  最後に finally で A が出力される。

- f10
  finally が先に実行され、1 秒後に 1 つ目の then が実行される。
  特に出力がないので、そのまま次の then が実行され、Y の Error が catch された。
  f9 との違い？

- f11
  X のエラーは catch できなかった　理由？

- f12
  コールバック関数で throw すると catch される
